Workbook

Sheet Inputs
A1: Huggies Project Financial Model (Demo)
A3: Years | B3: 2025 | C3: 2026 | D3: 2027
A5: Gross Margin % | B5: 0.55
A6: Tax rate % | B6: 0.2
A7: Working capital % of Revenue | B7: 0.1
A9: One-time Capex (2025) | B9: 100000 | C9: 0 | D9: 0
A11: Fixed OPEX (overall)
A12: Content & Creative Production | B12: 50000 | C12: 50000 | D12: 50000
A13: Tech & Operations (hosting/dev/qa) | B13: 30000 | C13: 30000 | D13: 30000
A14: CRM & Customer Service | B14: 20000 | C14: 20000 | D14: 20000
A16: Note:
A17: All yellow/blue cells are inputs. Model outputs are calculated automatically.
A18: Units: all monetary values are in RUB (change in these cells if needed).

Sheet Drivers
A1: Segment Drivers & Unit Economics (Inputs + Computed)
A3: Metric | B3: 2025 | C3: 2026 | D3: 2027
A5: Newborn (0-3m)
A6: Impressions (count) | B6: 5000000 | C6: 5000000 | D6: 5000000
A7: CTR | B7: 0.03 | C7: 0.03 | D7: 0.03
A8: Add-to-cart rate | B8: 0.12 | C8: 0.12 | D8: 0.12
A9: Trials (computed) | B9: =B6*B7*B8 | C9: =C6*C7*C8 | D9: =D6*D7*D8
A10: Revenue per trial (RUB) | B10: 900 | C10: 900 | D10: 900
A11: Repeat purchase rate @30d | B11: 0.08 | C11: 0.08 | D11: 0.08
A12: Repeat purchase rate @60d | B12: 0.06 | C12: 0.06 | D12: 0.06
A13: Total Revenue (RUB) | B13: =B9*B10*(1+B11+B12) | C13: =C9*C10*(1+C11+C12) | D13: =D9*D10*(1+D11+D12)
A14: Gross Margin (ref) | B14: =Inputs!$B$5 | C14: =Inputs!$B$5 | D14: =Inputs!$B$5
A15: COGS (RUB) | B15: =B13*(1-B14) | C15: =C13*(1-C14) | D15: =D13*(1-D14)
A16: CAC per trial (RUB) | B16: 120 | C16: 120 | D16: 120
A17: Marketing cost (RUB) | B17: =B9*B16 | C17: =C9*C16 | D17: =D9*D16
A18: Incentives per trial (RUB) | B18: 25 | C18: 25 | D18: 25
A19: Incentives cost (RUB) | B19: =B9*B18 | C19: =C9*C18 | D19: =D9*D18
A20: Segment EBIT (RUB) | B20: =B13-B15-B17-B19 | C20: =C13-C15-C17-C19 | D20: =D13-D15-D17-D19
A22: Active Babies (6-18m)
A23: Impressions (count) | B23: 5000000 | C23: 5000000 | D23: 5000000
A24: CTR | B24: 0.03 | C24: 0.03 | D24: 0.03
A25: Add-to-cart rate | B25: 0.12 | C25: 0.12 | D25: 0.12
A26: Trials (computed) | B26: =B23*B24*B25 | C26: =C23*C24*C25 | D26: =D23*D24*D25
A27: Revenue per trial (RUB) | B27: 900 | C27: 900 | D27: 900
A28: Repeat purchase rate @30d | B28: 0.08 | C28: 0.08 | D28: 0.08
A29: Repeat purchase rate @60d | B29: 0.06 | C29: 0.06 | D29: 0.06
A30: Total Revenue (RUB) | B30: =B26*B27*(1+B28+B29) | C30: =C26*C27*(1+C28+C29) | D30: =D26*D27*(1+D28+D29)
A31: Gross Margin (ref) | B31: =Inputs!$B$5 | C31: =Inputs!$B$5 | D31: =Inputs!$B$5
A32: COGS (RUB) | B32: =B30*(1-B31) | C32: =C30*(1-C31) | D32: =D30*(1-D31)
A33: CAC per trial (RUB) | B33: 120 | C33: 120 | D33: 120
A34: Marketing cost (RUB) | B34: =B26*B33 | C34: =C26*C33 | D34: =D26*D33
A35: Incentives per trial (RUB) | B35: 25 | C35: 25 | D35: 25
A36: Incentives cost (RUB) | B36: =B26*B35 | C36: =C26*C35 | D36: =D26*D35
A37: Segment EBIT (RUB) | B37: =B30-B32-B34-B36 | C37: =C30-C32-C34-C36 | D37: =D30-D32-D34-D36
A39: Night Protection (0-3m+)
A40: Impressions (count) | B40: 5000000 | C40: 5000000 | D40: 5000000
A41: CTR | B41: 0.03 | C41: 0.03 | D41: 0.03
A42: Add-to-cart rate | B42: 0.12 | C42: 0.12 | D42: 0.12
A43: Trials (computed) | B43: =B40*B41*B42 | C43: =C40*C41*C42 | D43: =D40*D41*D42
A44: Revenue per trial (RUB) | B44: 900 | C44: 900 | D44: 900
...

Sheet Totals
A1: Totals (Aggregated P&L + Unit Economics)
A3: Metric | B3: 2025 | C3: 2026 | D3: 2027
A5: Total Revenue | B5: =B13+B30+B47 | C5: =C13+C30+C47 | D5: =D13+D30+D47
A6: COGS | B6: =B15+B32+B49 | C6: =C15+C32+C49 | D6: =D15+D32+D49
A7: Marketing Cost | B7: =B17+B34+B51 | C7: =C17+C34+C51 | D7: =D17+D34+D51
A8: Incentives Cost | B8: =B19+B36+B53 | C8: =C19+C36+C53 | D8: =D19+D36+D53
A9: Fixed OPEX | B9: =Inputs!B12+Inputs!B13+Inputs!B14 | C9: =Inputs!C12+Inputs!C13+Inputs!C14 | D9: =Inputs!D12+Inputs!D13+Inputs!D14
A10: EBIT | B10: =B5-B6-B7-B8-B9 | C10: =C5-C6-C7-C8-C9 | D10: =D5-D6-D7-D8-D9
A11: Taxes | B11: =IF(B10>0,B10*Inputs!$B$6,0) | C11: =IF(C10>0,C10*Inputs!$B$6,0) | D11: =IF(D10>0,D10*Inputs!$B$6,0)
A12: Net Income | B12: =B10-B11 | C12: =C10-C11 | D12: =D10-D11

Sheet CashFlow
A1: Cash Flow (Simple)
A3: Metric | B3: 2025 | C3: 2026 | D3: 2027
A5: EBIT | B5: =Totals!B10 | C5: =Totals!C10 | D5: =Totals!D10
A6: Taxes | B6: =Totals!B11 | C6: =Totals!C11 | D6: =Totals!D11
A7: Cash from Ops (CFO) | B7: =B5-B6 | C7: =C5-C6 | D7: =D5-D6
A8: Capex | B8: =Inputs!B9 | C8: =Inputs!C9 | D8: =Inputs!D9
A9: Working Capital Change | B9: =Totals!B5*Inputs!$B$7 | C9: =Totals!C5*Inputs!$B$7 - Totals!B5*Inputs!$B$7 | D9: =Totals!D5*Inputs!$B$7 - Totals!C5*Inputs!$B$7
A10: Free Cash Flow (FCF) | B10: =B7 - B8 - B9 | C10: =C7 - C8 - C9 | D10: =D7 - D8 - D9
